<sdf version="1.6">
  <model name="PSM">
    <link name="base_link">
      <pose frame="">0 0 0 0 -0 0</pose>
      <inertial>
        <pose frame="">-0 -0.17016 -0.085607 0 -0 0</pose>
        <mass>2.0161</mass>
        <inertia>
          <ixx>0.03342853</ixx>
          <ixy>0.00942520</ixy>
          <ixz>-0.00334012</ixz>
          <iyy>0</iyy>
          <iyz>0</iyz>
          <izz>0.02897334</izz>
        </inertia>
      </inertial>
      <collision name="base_link_collision">
        <pose frame="">0 0 0 0 -0 0</pose>
        <geometry>
          <mesh>
            <scale>1 1 1</scale>
            <uri>model://PSM/meshes/base_link.STL</uri>
          </mesh>
        </geometry>
      </collision>
      <visual name="base_link_visual">
        <pose frame="">0 0 0 0 -0 0</pose>
        <geometry>
          <mesh>
            <scale>1 1 1</scale>
            <uri>model://PSM/meshes/base_link.STL</uri>
          </mesh>
        </geometry>
      </visual>
    </link>
    <link name="yaw_Link">
      <pose frame="">0 0 0 -1.57079 -1.57079 3.14159</pose>
      <inertial>
        <pose frame="">-0.0310590469894 -0.00784188715933 2.4984023851e-19 0 -0 0</pose>
        <mass>5.000015647211163</mass>
        <inertia>
          <ixx>61.2316222250788</ixx>
          <ixy>-4.94018941606857</ixy>
          <ixz>3.30290454621193e-17</ixz>
          <iyy>177.387057831416</iyy>
          <iyz>-4.24275658401527e-16</iyz>
          <izz>0.000837061743873544</izz>
        </inertia>
      </inertial>
      <collision name="yaw_Link_collision">
        <pose frame="">0 0 0 0 -0 0</pose>
        <geometry>
          <mesh>
            <scale>1 1 1</scale>
            <uri>model://PSM/meshes/yaw_Link.STL</uri>
          </mesh>
        </geometry>
      </collision>
      <visual name="yaw_Link_visual">
        <pose frame="">0 0 0 0 -0 0</pose>
        <geometry>
          <mesh>
            <scale>1 1 1</scale>
            <uri>model://PSM/meshes/yaw_Link.STL</uri>
          </mesh>
        </geometry>
      </visual>
    </link>
    <joint name="yaw_joint" type="revolute">
      <child>yaw_Link</child>
      <parent>base_link</parent>
      <axis>
        <xyz>-4e-06 1 -0</xyz>
        <limit>
          <lower>-1.605</lower>
          <upper>1.5994</upper>
          <effort>1000</effort>
          <velocity>10</velocity>
        </limit>
        <dynamics>
          <spring_reference>0</spring_reference>
          <spring_stiffness>0</spring_stiffness>
        </dynamics>
        <use_parent_model_frame>1</use_parent_model_frame>
      </axis>
    </joint>
    <link name="pitch_back_Link">
      <pose frame="">0 -0.0296 0 1.57081 -1.28007 -1.5708</pose>
      <inertial>
        <pose frame="">-0.0517090332465 -0.00908821616997 -0.0102599097095 0 -0 0</pose>
        
        <mass>0.995272698572072</mass>
        <inertia>
          <ixx>0.000772323398184249</ixx>
          <ixy>0.00183425003290997</ixy>
          <ixz>0.00133487363923200</ixz>
          <iyy>9.78466855460110e-5</iyy>
          <iyz>-0.000340590547336448</iyz>
          <izz>0.0001</izz>
        </inertia>
      </inertial>
      <collision name="pitch_back_Link_collision">
        <pose frame="">0 0 0 0 -0 0</pose>
        <geometry>
          <mesh>
            <scale>1 1 1</scale>
            <uri>model://PSM/meshes/pitch_back_Link.STL</uri>
          </mesh>
        </geometry>
      </collision>
      <visual name="pitch_back_Link_visual">
        <pose frame="">0 0 0 0 -0 0</pose>
        <geometry>
          <mesh>
            <scale>1 1 1</scale>
            <uri>model://PSM/meshes/pitch_back_Link.STL</uri>
          </mesh>
        </geometry>
      </visual>
    </link>
    <joint name="pitch_back_joint" type="revolute">
      <child>pitch_back_Link</child>
      <parent>yaw_Link</parent>
      <axis>
        <xyz>-1 -0 -3e-06</xyz>
        <limit>
          <lower>-0.93556</lower>
          <upper>0.94249</upper>
          <effort>1000</effort>
          <velocity>10</velocity>
        </limit>
        <dynamics>
          <spring_reference>0</spring_reference>
          <spring_stiffness>0</spring_stiffness>
        </dynamics>
        <use_parent_model_frame>1</use_parent_model_frame>
      </axis>
    </joint>
     <link name='counterweight_Link'>
      <pose frame=''>-0 -0.1296 -0 5e-06 -2.6e-05 1.57079</pose>
      <inertial>
        <pose frame=''>0.008649 -1e-06 -0.042832 0 -0 0</pose>
        <mass>0.0572295</mass>
        <inertia>
          <ixx>0.001</ixx>
          <ixy>0.00001</ixy>
          <ixz>0.00001</ixz>
          <iyy>0.001</iyy>
          <iyz>0.00001</iyz>
          <izz>0.001</izz>
        </inertia>
      </inertial>
      <collision name='counterweight_Link_collision'>
        <pose frame=''>0 0 0 0 -0 0</pose>
        <geometry>
          <mesh>
            <scale>1 1 1</scale>
            <uri>model://PSM/meshes/counterweight_Link.STL</uri>
          </mesh>
        </geometry>
      </collision>
      <visual name='counterweight_Link_visual'>
        <pose frame=''>0 0 0 0 -0 0</pose>
        <geometry>
          <mesh>
            <scale>1 1 1</scale>
            <uri>model://PSM/meshes/counterweight_Link.STL</uri>
          </mesh>
        </geometry>
      </visual>
    </link>
    <joint name='counterweight_joint' type='prismatic'>
      <child>counterweight_Link</child>
      <parent>pitch_back_Link</parent>
      <axis>
        <xyz>5e-06 -2.6e-05 1</xyz>
        <limit>
          <lower>0</lower>
          <upper>0.15</upper>
          <effort>1000</effort>
          <velocity>10</velocity>
        </limit>
        <dynamics>
          <spring_reference>0</spring_reference>
          <spring_stiffness>0</spring_stiffness>
        </dynamics>
        <use_parent_model_frame>1</use_parent_model_frame>
      </axis>
    </joint>
    <link name="pitch_bottom_Link">
      <pose frame="">-0 -0.072598 0.143705 -1.5708 -2.6e-05 1.5708</pose>
      <inertial>
        <pose frame="">4.31649186338e-06 -0.0152173761625 -0.0034845563181 0 -0 0</pose>
        <mass>0.02577503304336412</mass>
        <inertia>
          <ixx>0.000817528369358298</ixx>
          <ixy>-7.88994012604494e-10</ixy>
          <ixz>-9.24077819930272e-10</ixz>
          <iyy>106.174159728670</iyy>
          <iyz>44.0035891460680</iyz>
          <izz>152.019481939598</izz>
        </inertia>
      </inertial>
      <collision name="pitch_bottom_Link_collision">
        <pose frame="">0 0 0 0 -0 0</pose>
        <geometry>
          <mesh>
            <scale>1 1 1</scale>
            <uri>model://PSM/meshes/pitch_bottom_Link.STL</uri>
          </mesh>
        </geometry>
      </collision>
      <visual name="pitch_bottom_Link_visual">
        <pose frame="">0 0 0 0 -0 0</pose>
        <geometry>
          <mesh>
            <scale>1 1 1</scale>
            <uri>model://PSM/meshes/pitch_bottom_Link.STL</uri>
          </mesh>
        </geometry>
      </visual>
    </link>
    <joint name="pitch_bottom_joint" type="revolute">
      <child>pitch_bottom_Link</child>
      <parent>pitch_back_Link</parent>
      <axis>
        <xyz>-1 -0 -3e-06</xyz>
        <limit>
          <lower>-0.94249</lower>
          <upper>0.93556</upper>
          <effort>1000</effort>
          <velocity>10</velocity>
        </limit>
        <dynamics>
          <spring_reference>0</spring_reference>
          <spring_stiffness>0</spring_stiffness>
        </dynamics>
        <use_parent_model_frame>1</use_parent_model_frame>
      </axis>
    </joint>
    <link name="pitch_end_Link">
      <pose frame="">-0 0.443402 0.143719 -1.5708 -2.6e-05 1.5708</pose>
      <inertial>
        <pose frame="">0.0182917493619 -0.278260779718 -0.0215864302913 0 -0 0</pose>
        
        <mass>0.15412072935627902</mass>
        <inertia>
          <ixx>0.0116971838932095</ixx>
          <ixy>-0.00497921812635106</ixy>
          <ixz>-0.000704753411479932</ixz>
          <iyy>0.00271981531827910</iyy>
          <iyz>-0.000105475678845879</iyz>
          <izz>0.0001</izz>
        </inertia>
      </inertial>
      <collision name="pitch_end_Link_collision">
        <pose frame="">0 0 0 0 -0 0</pose>
        <geometry>
          <mesh>
            <scale>1 1 1</scale>
            <uri>model://PSM/meshes/pitch_end_Link.STL</uri>
          </mesh>
        </geometry>
      </collision>
      <visual name="pitch_end_Link_visual">
        <pose frame="">0 0 0 0 -0 0</pose>
        <geometry>
          <mesh>
            <scale>1 1 1</scale>
            <uri>model://PSM/meshes/pitch_end_Link.STL</uri>
          </mesh>
        </geometry>
      </visual>
    </link>
    <joint name="pitch_end_joint" type="revolute">
      <child>pitch_end_Link</child>
      <parent>pitch_bottom_Link</parent>
      <axis>
        <xyz>-1 -0 -3e-06</xyz>
        <limit>
          <lower>-0.93556</lower>
          <upper>0.94249</upper>
          <effort>1000</effort>
          <velocity>10</velocity>
        </limit>
        <dynamics>
          <spring_reference>0</spring_reference>
          <spring_stiffness>0</spring_stiffness>
        </dynamics>
        <use_parent_model_frame>1</use_parent_model_frame>
      </axis>
    </joint>
    <link name="main_insertion_Link">
      <pose frame="">-1e-06 0.486395 0.43181 -3.14159 1.9e-05 -1.5708</pose>
      <inertial>
        <pose frame="">0.0232580742088 -0.971807785323 -0.0139461572359 0 -0 0</pose>
        <mass>0.06971952427545924</mass>
        <inertia>
          

          <ixx>0.0001</ixx>
          <ixy>-0.000826139276916676</ixy>
          <ixz>0.00219488032351328</ixz>
          <iyy>0.00531219015037077</iyy>
          <iyz>0.00368908516314349</iyz>
          <izz>0.0300238694117230</izz>
        </inertia>
      </inertial>
      <collision name="main_insertion_Link_collision">
        <pose frame="">0 0 0 0 -0 0</pose>
        <geometry>
          <mesh>
            <scale>1 1 1</scale>
            <uri>model://PSM/meshes/main_insertion_Link.STL</uri>
          </mesh>
        </geometry>
      </collision>
      <visual name="main_insertion_Link_visual">
        <pose frame="">0 0 0 0 -0 0</pose>
        <geometry>
          <mesh>
            <scale>1 1 1</scale>
            <uri>model://PSM/meshes/main_insertion_Link.STL</uri>
          </mesh>
        </geometry>
      </visual>
    </link>
    <joint name="main_insertion_joint" type="prismatic">
      <child>main_insertion_Link</child>
      <parent>pitch_end_Link</parent>
      <axis>
        <xyz>-6e-06 -1.9e-05 -1</xyz>
        <limit>
          <lower>0</lower>
          <upper>0.24</upper>
          <effort>1000</effort>
          <velocity>1</velocity>
        </limit>
        <dynamics>
          <spring_reference>0</spring_reference>
          <spring_stiffness>0</spring_stiffness>
        </dynamics>
        <use_parent_model_frame>1</use_parent_model_frame>
      </axis>
    </joint>
    <link name="tool_roll_link">
      <pose frame="">2e-06 0.486403 0.01561 3.14159 -1.9e-05 1.57079</pose>
      <inertial>
        <pose frame="">-0 -0 -0.005823 0 -0 0</pose>
        
        <mass>0.012491</mass>
        <inertia>
          <ixx>0.001</ixx>
          <ixy>0.00001</ixy>
          <ixz>0.00001</ixz>
          <iyy>0.001</iyy>
          <iyz>0.00001</iyz>
          <izz>0.001</izz>
        </inertia>
      </inertial>
      <collision name="tool_roll_link_collision">
        <pose frame="">0 0 0 0 -0 0</pose>
        <geometry>
          <mesh>
            <scale>1 1 1</scale>
            <uri>model://PSM/meshes/tool_roll_link.STL</uri>
          </mesh>
        </geometry>
      </collision>
      <visual name="tool_roll_link_visual">
        <pose frame="">0 0 0 0 -0 0</pose>
        <geometry>
          <mesh>
            <scale>1 1 1</scale>
            <uri>model://PSM/meshes/tool_roll_link.STL</uri>
          </mesh>
        </geometry>
      </visual>
    </link>
    <joint name="tool_roll_joint" type="revolute">
      <child>tool_roll_link</child>
      <parent>main_insertion_Link</parent>
      <axis>
        <xyz>-6e-06 -1.9e-05 -1</xyz>
        <limit>
          <lower>-3.14159</lower>
          <upper>3.14159</upper>
          <effort>1000</effort>
          <velocity>10</velocity>
        </limit>
        <dynamics>
          <spring_reference>0</spring_reference>
          <spring_stiffness>0</spring_stiffness>
        </dynamics>
        <use_parent_model_frame>1</use_parent_model_frame>
      </axis>
    </joint>
    <link name="tool_pitch_link">
      <pose frame="">2e-06 0.486403 0.01561 -1.96086 1.57078 1.18072</pose>
      <inertial>
        <pose frame="">0.003576 -0 4e-06 0 -0 0</pose>
        
        <mass>0.012491</mass>
        <inertia>
          
    
          <ixx>0.001</ixx>
          <ixy>0.00001</ixy>
          <ixz>0.00001</ixz>
          <iyy>0.001</iyy>
          <iyz>0.00001</iyz>
          <izz>0.001</izz>
        </inertia>
      </inertial>
      <collision name="tool_pitch_link_collision">
        <pose frame="">0 0 0 0 -0 0</pose>
        <geometry>
          <mesh>
            <scale>1 1 1</scale>
            <uri>model://PSM/meshes/tool_pitch_link.STL</uri>
          </mesh>
        </geometry>
      </collision>
      <visual name="tool_pitch_link_visual">
        <pose frame="">0 0 0 0 -0 0</pose>
        <geometry>
          <mesh>
            <scale>1 1 1</scale>
            <uri>model://PSM/meshes/tool_pitch_link.STL</uri>
          </mesh>
        </geometry>
      </visual>
    </link>
    <joint name="tool_pitch_joint" type="revolute">
      <child>tool_pitch_link</child>
      <parent>tool_roll_link</parent>
      <axis>
        <xyz>1 -1.1e-05 6e-06</xyz>
        <limit>
          <lower>-1.5708</lower>
          <upper>1.5708</upper>
          <effort>1000</effort>
          <velocity>10</velocity>
        </limit>
        <dynamics>
          <spring_reference>0</spring_reference>
          <spring_stiffness>0</spring_stiffness>
        </dynamics>
        <use_parent_model_frame>1</use_parent_model_frame>
      </axis>
    </joint>
    <link name="tool_yaw_link">
      <pose frame="">2e-06 0.486403 0.00651 1.57078 3e-06 3.14158</pose>
      <inertial>
        <pose frame="">-0 -0 -5e-05 0 -0 0</pose>
        
        
        <mass>0.012491</mass>
        <inertia>
          <ixx>0.001</ixx>
          <ixy>0.00001</ixy>
          <ixz>0.00001</ixz>
          <iyy>0.001</iyy>
          <iyz>0.00001</iyz>
          <izz>0.001</izz>
        </inertia>
      </inertial>
      <collision name="tool_yaw_link_collision">
        <pose frame="">0 0 0 0 -0 0</pose>
        <geometry>
          <mesh>
            <scale>1 1 1</scale>
            <uri>model://PSM/meshes/tool_yaw_link.STL</uri>
          </mesh>
        </geometry>
      </collision>
      <visual name="tool_yaw_link_visual">
        <pose frame="">0 0 0 0 -0 0</pose>
        <geometry>
          <mesh>
            <scale>1 1 1</scale>
            <uri>model://PSM/meshes/tool_yaw_link.STL</uri>
          </mesh>
        </geometry>
      </visual>
    </link>
    <joint name="tool_yaw_joint" type="revolute">
      <child>tool_yaw_link</child>
      <parent>tool_pitch_link</parent>
      <axis>
        <xyz>1.1e-05 1 1.2e-05</xyz>
        <limit>
          <lower>-1.5708</lower>
          <upper>1.5708</upper>
          <effort>1000</effort>
          <velocity>10</velocity>
        </limit>
        <dynamics>
          <spring_reference>0</spring_reference>
          <spring_stiffness>0</spring_stiffness>
        </dynamics>
        <use_parent_model_frame>1</use_parent_model_frame>
      </axis>
    </joint>

    <link name="tool_gripper1_link">
      
      <pose frame="">2e-06 0.486403 0.00651 1.57078 3.14158 3.14158</pose>
      <inertial>
        <pose frame="">0.000196 0.001435 -0.000885 0 -0 0</pose>
        
        <mass>0.010491</mass>
        
        <inertia>
          <ixx>0.001</ixx>
          <ixy>0.00001</ixy>
          <ixz>0.00001</ixz>
          <iyy>0.001</iyy>
          <iyz>0.00001</iyz>
          <izz>0.001</izz>
        </inertia>
      </inertial>
      <collision name="tool_gripper1_link_collision">
        <pose frame="">0 0 0 0 -0 0</pose>
        <geometry>
          <mesh>
            <scale>1 1 1</scale>
            <uri>model://PSM/meshes/tool_gripper1_link.STL</uri>
          </mesh>
        </geometry>
      </collision>
      <visual name="tool_gripper1_link_visual">
        <pose frame="">0 0 0 0 -0 0</pose>
        <geometry>
          <mesh>
            <scale>1 1 1</scale>
            <uri>model://PSM/meshes/tool_gripper1_link.STL</uri>
          </mesh>
        </geometry>
      </visual>
    </link>
    <joint name="tool_gripper1_joint" type="revolute">
      <child>tool_gripper1_link</child>
      <parent>tool_yaw_link</parent>
      <axis>
        <xyz>1.1e-05 -1 1.2e-05</xyz>
        <limit>
          <lower>0</lower>
          <upper>1</upper>
          <effort>0</effort>
          <velocity>0</velocity>
        </limit>
        <dynamics>
          <spring_reference>0</spring_reference>
          <spring_stiffness>0</spring_stiffness>
        </dynamics>
        <use_parent_model_frame>1</use_parent_model_frame>
      </axis>
    </joint>
    <link name="tool_gripper2_link">
      
      <pose frame="">2e-06 0.486403 0.00651 1.57078 3.14158 3.14158</pose>
      <inertial>
        <pose frame="">-0.000196 0.001435 0.000885 0 -0 0</pose>
        
        <mass>0.010491</mass>
        <inertia>
          <ixx>0.001</ixx>
          <ixy>0.00001</ixy>
          <ixz>0.00001</ixz>
          <iyy>0.001</iyy>
          <iyz>0.00001</iyz>
          <izz>0.001</izz>
        </inertia>
      </inertial>
      <collision name="tool_gripper2_link_collision">
        <pose frame="">0 0 0 0 -0 0</pose>
        <geometry>
          <mesh>
            <scale>1 1 1</scale>
            <uri>model://PSM/meshes/tool_gripper2_link.STL</uri>
          </mesh>
        </geometry>
      </collision>
      <visual name="tool_gripper2_link_visual">
        <pose frame="">0 0 0 0 -0 0</pose>
        <geometry>
          <mesh>
            <scale>1 1 1</scale>
            <uri>model://PSM/meshes/tool_gripper2_link.STL</uri>
          </mesh>
        </geometry>
      </visual>
    </link>
    <joint name="tool_gripper2_joint" type="revolute">
      <child>tool_gripper2_link</child>
      <parent>tool_yaw_link</parent>
      <axis>
        <xyz>1.1e-05 1 1.2e-05</xyz>
        <limit>
          <lower>0</lower>
          <upper>1</upper>
          <effort>0</effort>
          <velocity>0</velocity>
        </limit>
        <dynamics>
          <spring_reference>0</spring_reference>
          <spring_stiffness>0</spring_stiffness>
        </dynamics>
        <use_parent_model_frame>1</use_parent_model_frame>
      </axis>
    </joint>
    <link name="pitch_top_Link">
      <pose frame="">-0 -0.068718 0.18 -1.5708 -2.6e-05 1.5708</pose>
      <inertial>
        <pose frame="">5.38491367596e-06 -0.00106748644867 -0.00697456679153 0 -0 0</pose>
        <mass>0.016872183783368622</mass>
        <inertia>
          <ixx>0.000818242985843265</ixx>
          <ixy>-3.27502246031649e-10</ixy>
          <ixz>-5.85524017437777e-10</ixz>
          <iyy>83.2919096852399</iyy>
          <iyz>51.0595979731958</iyz>
          <izz>175.161036445023</izz>
        </inertia>
      </inertial>
      <collision name="pitch_top_Link_collision">
        <pose frame="">0 0 0 0 -0 0</pose>
        <geometry>
          <mesh>
            <scale>1 1 1</scale>
            <uri>model://PSM/meshes/pitch_top_Link.STL</uri>
          </mesh>
        </geometry>
      </collision>
      <visual name="pitch_top_Link_visual">
        <pose frame="">0 0 0 0 -0 0</pose>
        <geometry>
          <mesh>
            <scale>1 1 1</scale>
            <uri>model://PSM/meshes/pitch_top_Link.STL</uri>
          </mesh>
        </geometry>
      </visual>
    </link>
    <joint name="pitch_top_joint" type="revolute">
      <child>pitch_top_Link</child>
      <parent>pitch_back_Link</parent>
      <axis>
        <xyz>-1 -0 -3e-06</xyz>
        <limit>
          <lower>-0.94249</lower>
          <upper>0.93556</upper>
          <effort>1000</effort>
          <velocity>10</velocity>
        </limit>
        <dynamics>
          <spring_reference>0</spring_reference>
          <spring_stiffness>0</spring_stiffness>
        </dynamics>
        <use_parent_model_frame>1</use_parent_model_frame>
      </axis>
    </joint>
    <link name="pitch_front_Link">
      <pose frame="">-0 0.0664 -0 1.57081 -1.28007 -1.5708</pose>
      <inertial>
        <pose frame="">0.20547488196 0.0167446469739 0.0108828998382 0 -0 0</pose>
        <mass>0.1509199452744319</mass>
        <inertia>
          <ixx>0.000763256639509961</ixx>
          <ixy>0.00192212034862649</ixy>
          <ixz>0.000970612187327085</ixz>
          <iyy>0.00188347852015523</iyy>
          <iyz>-0.000381705112837480</iyz>
          <izz>0.0001</izz>
        </inertia>
      </inertial>
      <collision name="pitch_front_Link_collision">
        <pose frame="">0 0 0 0 -0 0</pose>
        <geometry>
          <mesh>
            <scale>1 1 1</scale>
            <uri>model://PSM/meshes/pitch_front_Link.STL</uri>
          </mesh>
        </geometry>
      </collision>
      <visual name="pitch_front_Link_visual">
        <pose frame="">0 0 0 0 -0 0</pose>
        <geometry>
          <mesh>
            <scale>1 1 1</scale>
            <uri>model://PSM/meshes/pitch_front_Link.STL</uri>
          </mesh>
        </geometry>
      </visual>
    </link>
    <joint name="pitch_front_joint" type="revolute">
      <child>pitch_front_Link</child>
      <parent>yaw_Link</parent>
      <axis>
        <xyz>-1 -0 -3e-06</xyz>
        <limit>
          <lower>-0.93556</lower>
          <upper>0.94249</upper>
          <effort>1000</effort>
          <velocity>10</velocity>
        </limit>
        <dynamics>
          <spring_reference>0</spring_reference>
          <spring_stiffness>0</spring_stiffness>
        </dynamics>
        <use_parent_model_frame>1</use_parent_model_frame>
      </axis>
    </joint>

    <joint name="pitch_front_bottom_joint" type="revolute">
      <pose>0.096 0 0 0 0 0 </pose>
      <child>pitch_bottom_Link</child>
      <parent>pitch_front_Link</parent>
      <axis>
        <xyz>-1 0 0</xyz>
        <limit>
          <lower>-0.93556</lower>
          <upper>0.94249</upper>
          <effort>1000</effort>
          <velocity>1</velocity>
        </limit>
        <dynamics>
          <spring_reference>0</spring_reference>
          <spring_stiffness>0</spring_stiffness>
        </dynamics>
        <use_parent_model_frame>1</use_parent_model_frame>
      </axis>
    </joint>

    <joint name="pitch_top_end_joint" type="revolute">
      <pose>0.00388 -0.036293189  0 0 0 0 </pose>
      <child>pitch_end_Link</child>
      <parent>pitch_top_Link</parent>
      <axis>
        <xyz>-1 0 0</xyz>
        <limit>
          <lower>-0.93556</lower>
          <upper>0.94249</upper>
          <effort>1000</effort>
          <velocity>1</velocity>
        </limit>
        <dynamics>
          <spring_reference>0</spring_reference>
          <spring_stiffness>0</spring_stiffness>
        </dynamics>
        <use_parent_model_frame>1</use_parent_model_frame>
      </axis>
    </joint>
  </model>
</sdf>