<sdf version="1.6">
  <model name="PSM">
    <link name="base_link">
      <pose frame="">0 0 0 0 -0 0</pose>
      <inertial>
        <pose frame="">-0 -0.17016 -0.085607 0 -0 0</pose>
        <mass>2.0161</mass>
        <inertia>
          <ixx>0.03342853</ixx>
          <ixy>0.00942520</ixy>
          <ixz>-0.00334012</ixz>
          <iyy>0</iyy>
          <iyz>0</iyz>
          <izz>0.02897334</izz>
        </inertia>
      </inertial>
      <collision name="base_link_collision">
        <pose frame="">0 0 0 0 -0 0</pose>
        <geometry>
          <mesh>
            <scale>1 1 1</scale>
            <uri>model://PSM/meshes/base_link.STL</uri>
          </mesh>
        </geometry>
      </collision>
      <visual name="base_link_visual">
        <pose frame="">0 0 0 0 -0 0</pose>
        <geometry>
          <mesh>
            <scale>1 1 1</scale>
            <uri>model://PSM/meshes/base_link.STL</uri>
          </mesh>
        </geometry>
      </visual>
    </link>
    <link name="yaw_Link">
      <pose frame="">0 0 0 -1.57079 -1.57079 3.14159</pose>
      <inertial>
        <pose frame="">-0.0135859574008 0.00478440248423 1.40492515923e-20 0 -0 0</pose>
        <mass>0.5000595627320654</mass>
        <inertia>
          <ixx>25.7390484183</ixx>
          <ixy>1.07486174669</ixy>
          <ixz>1.61901785097e-18</ixz>
          <iyy>73.3841429489</iyy>
          <iyz>5.43742483502e-18</iyz>
          <izz>0.00259265277504</izz>
        </inertia>
      </inertial>
      <collision name="yaw_Link_collision">
        <pose frame="">0 0 0 0 -0 0</pose>
        <geometry>
          <mesh>
            <scale>1 1 1</scale>
            <uri>model://PSM/meshes/yaw_Link.STL</uri>
          </mesh>
        </geometry>
      </collision>
      <visual name="yaw_Link_visual">
        <pose frame="">0 0 0 0 -0 0</pose>
        <geometry>
          <mesh>
            <scale>1 1 1</scale>
            <uri>model://PSM/meshes/yaw_Link.STL</uri>
          </mesh>
        </geometry>
      </visual>
    </link>
    <joint name="yaw_joint" type="revolute">
      <child>yaw_Link</child>
      <parent>base_link</parent>
      <axis>
        <xyz>-4e-06 1 -0</xyz>
        <limit>
          <lower>-1.605</lower>
          <upper>1.5994</upper>
          <effort>1000</effort>
          <velocity>10</velocity>
        </limit>
        <dynamics>
          <spring_reference>0</spring_reference>
          <spring_stiffness>0</spring_stiffness>
        </dynamics>
        <use_parent_model_frame>1</use_parent_model_frame>
      </axis>
    </joint>
    <link name="pitch_back_Link">
      <pose frame="">0 -0.0296 0 1.57081 -1.28007 -1.5708</pose>
      <inertial>
        <pose frame="">-0.0312086244015 -0.00876552845787 -0.00582022580812 0 -0 0</pose>
        
        <mass>1.500141319120808</mass>
        <inertia>
          <ixx>0.002078304379</ixx>
          <ixy>0.0011901125136</ixy>
          <ixz>0.000386743430594</ixz>
          <iyy>8.22408027701e-05</iyy>
          <iyz>0.000909713694266</iyz>
          <izz>0.0117703004594</izz>
        </inertia>
      </inertial>
      <collision name="pitch_back_Link_collision">
        <pose frame="">0 0 0 0 -0 0</pose>
        <geometry>
          <mesh>
            <scale>1 1 1</scale>
            <uri>model://PSM/meshes/pitch_back_Link.STL</uri>
          </mesh>
        </geometry>
      </collision>
      <visual name="pitch_back_Link_visual">
        <pose frame="">0 0 0 0 -0 0</pose>
        <geometry>
          <mesh>
            <scale>1 1 1</scale>
            <uri>model://PSM/meshes/pitch_back_Link.STL</uri>
          </mesh>
        </geometry>
      </visual>
    </link>
    <joint name="pitch_back_joint" type="revolute">
      <child>pitch_back_Link</child>
      <parent>yaw_Link</parent>
      <axis>
        <xyz>-1 -0 -3e-06</xyz>
        <limit>
          <lower>-0.93556</lower>
          <upper>0.94249</upper>
          <effort>1000</effort>
          <velocity>10</velocity>
        </limit>
        <dynamics>
          <spring_reference>0</spring_reference>
          <spring_stiffness>0</spring_stiffness>
        </dynamics>
        <use_parent_model_frame>1</use_parent_model_frame>
      </axis>
    </joint>
    <link name="pitch_bottom_Link">
      <pose frame="">-0 -0.072598 0.143705 -1.5708 -2.6e-05 1.5708</pose>
      <inertial>
        <pose frame="">-1.30933617056e-06 0.0306333912282 0.00529110644269 0 -0 0</pose>
        <mass>0.019462555863818884</mass>
        <inertia>
          <ixx>0.00262149257305</ixx>
          <ixy>8.41195740181e-10</ixy>
          <ixz>2.6403294956e-10</ixz>
          <iyy>72.3397921876</iyy>
          <iyz>16.9173223277</iyz>
          <izz>87.0028394056</izz>
        </inertia>
      </inertial>
      <collision name="pitch_bottom_Link_collision">
        <pose frame="">0 0 0 0 -0 0</pose>
        <geometry>
          <mesh>
            <scale>1 1 1</scale>
            <uri>model://PSM/meshes/pitch_bottom_Link.STL</uri>
          </mesh>
        </geometry>
      </collision>
      <visual name="pitch_bottom_Link_visual">
        <pose frame="">0 0 0 0 -0 0</pose>
        <geometry>
          <mesh>
            <scale>1 1 1</scale>
            <uri>model://PSM/meshes/pitch_bottom_Link.STL</uri>
          </mesh>
        </geometry>
      </visual>
    </link>
    <joint name="pitch_bottom_joint" type="revolute">
      <child>pitch_bottom_Link</child>
      <parent>pitch_back_Link</parent>
      <axis>
        <xyz>-1 -0 -3e-06</xyz>
        <limit>
          <lower>-0.94249</lower>
          <upper>0.93556</upper>
          <effort>1000</effort>
          <velocity>10</velocity>
        </limit>
        <dynamics>
          <spring_reference>0</spring_reference>
          <spring_stiffness>0</spring_stiffness>
        </dynamics>
        <use_parent_model_frame>1</use_parent_model_frame>
      </axis>
    </joint>
    <link name="pitch_end_Link">
      <pose frame="">-0 0.443402 0.143719 -1.5708 -2.6e-05 1.5708</pose>
      <inertial>
        <pose frame="">0.0693490842112 0.219074121622 0.00283407549509 0 -0 0</pose>
        
        <mass>0.009735009858086972</mass>
        <inertia>
          <ixx>0.000196255087522</ixx>
          <ixy>0.000436088930915</ixy>
          <ixz>0.000994561559283</ixz>
          <iyy>0.00258199509082</iyy>
          <iyz>0.000101552489171</iyz>
          <izz>0.0121727430654</izz>
        </inertia>
      </inertial>
      <collision name="pitch_end_Link_collision">
        <pose frame="">0 0 0 0 -0 0</pose>
        <geometry>
          <mesh>
            <scale>1 1 1</scale>
            <uri>model://PSM/meshes/pitch_end_Link.STL</uri>
          </mesh>
        </geometry>
      </collision>
      <visual name="pitch_end_Link_visual">
        <pose frame="">0 0 0 0 -0 0</pose>
        <geometry>
          <mesh>
            <scale>1 1 1</scale>
            <uri>model://PSM/meshes/pitch_end_Link.STL</uri>
          </mesh>
        </geometry>
      </visual>
    </link>
    <joint name="pitch_end_joint" type="revolute">
      <child>pitch_end_Link</child>
      <parent>pitch_bottom_Link</parent>
      <axis>
        <xyz>-1 -0 -3e-06</xyz>
        <limit>
          <lower>-0.93556</lower>
          <upper>0.94249</upper>
          <effort>1000</effort>
          <velocity>10</velocity>
        </limit>
        <dynamics>
          <spring_reference>0</spring_reference>
          <spring_stiffness>0</spring_stiffness>
        </dynamics>
        <use_parent_model_frame>1</use_parent_model_frame>
      </axis>
    </joint>
    <link name="main_insertion_Link">
      <pose frame="">-1e-06 0.486395 0.43181 -3.14159 1.9e-05 -1.5708</pose>
      <inertial>
        <pose frame="">0.131833294978 -1.74400500973 0.485357376645 0 -0 0</pose>
        <mass>0.049362827222935036</mass>
        <inertia>
          

          <ixx>0.0730964910782</ixx>
          <ixy>0.00594770562795</ixy>
          <ixz>0.000999004174498</ixz>
          <iyy>0.000726566558674</iyy>
          <iyz>0.00585284362105</iyz>
          <izz>0.0242513233653</izz>
        </inertia>
      </inertial>
      <collision name="main_insertion_Link_collision">
        <pose frame="">0 0 0 0 -0 0</pose>
        <geometry>
          <mesh>
            <scale>1 1 1</scale>
            <uri>model://PSM/meshes/main_insertion_Link.STL</uri>
          </mesh>
        </geometry>
      </collision>
      <visual name="main_insertion_Link_visual">
        <pose frame="">0 0 0 0 -0 0</pose>
        <geometry>
          <mesh>
            <scale>1 1 1</scale>
            <uri>model://PSM/meshes/main_insertion_Link.STL</uri>
          </mesh>
        </geometry>
      </visual>
    </link>
    <joint name="main_insertion_joint" type="prismatic">
      <child>main_insertion_Link</child>
      <parent>pitch_end_Link</parent>
      <axis>
        <xyz>-6e-06 -1.9e-05 -1</xyz>
        <limit>
          <lower>0</lower>
          <upper>0.24</upper>
          <effort>1000</effort>
          <velocity>1</velocity>
        </limit>
        <dynamics>
          <spring_reference>0</spring_reference>
          <spring_stiffness>0</spring_stiffness>
        </dynamics>
        <use_parent_model_frame>1</use_parent_model_frame>
      </axis>
    </joint>
    <link name="tool_roll_link">
      <pose frame="">2e-06 0.486403 0.01561 3.14159 -1.9e-05 1.57079</pose>
      <inertial>
        <pose frame="">-0 -0 -0.005823 0 -0 0</pose>
        
        <mass>0.012491</mass>
        <inertia>
          <ixx>0.001</ixx>
          <ixy>0.00001</ixy>
          <ixz>0.00001</ixz>
          <iyy>0.001</iyy>
          <iyz>0.00001</iyz>
          <izz>0.001</izz>
        </inertia>
      </inertial>
      <collision name="tool_roll_link_collision">
        <pose frame="">0 0 0 0 -0 0</pose>
        <geometry>
          <mesh>
            <scale>1 1 1</scale>
            <uri>model://PSM/meshes/tool_roll_link.STL</uri>
          </mesh>
        </geometry>
      </collision>
      <visual name="tool_roll_link_visual">
        <pose frame="">0 0 0 0 -0 0</pose>
        <geometry>
          <mesh>
            <scale>1 1 1</scale>
            <uri>model://PSM/meshes/tool_roll_link.STL</uri>
          </mesh>
        </geometry>
      </visual>
    </link>
    <joint name="tool_roll_joint" type="revolute">
      <child>tool_roll_link</child>
      <parent>main_insertion_Link</parent>
      <axis>
        <xyz>-6e-06 -1.9e-05 -1</xyz>
        <limit>
          <lower>-3.14159</lower>
          <upper>3.14159</upper>
          <effort>1000</effort>
          <velocity>10</velocity>
        </limit>
        <dynamics>
          <spring_reference>0</spring_reference>
          <spring_stiffness>0</spring_stiffness>
        </dynamics>
        <use_parent_model_frame>1</use_parent_model_frame>
      </axis>
    </joint>
    <link name="tool_pitch_link">
      <pose frame="">2e-06 0.486403 0.01561 -1.96086 1.57078 1.18072</pose>
      <inertial>
        <pose frame="">0.003576 -0 4e-06 0 -0 0</pose>
        
        <mass>0.012491</mass>
        <inertia>
          
    
          <ixx>0.001</ixx>
          <ixy>0.00001</ixy>
          <ixz>0.00001</ixz>
          <iyy>0.001</iyy>
          <iyz>0.00001</iyz>
          <izz>0.001</izz>
        </inertia>
      </inertial>
      <collision name="tool_pitch_link_collision">
        <pose frame="">0 0 0 0 -0 0</pose>
        <geometry>
          <mesh>
            <scale>1 1 1</scale>
            <uri>model://PSM/meshes/tool_pitch_link.STL</uri>
          </mesh>
        </geometry>
      </collision>
      <visual name="tool_pitch_link_visual">
        <pose frame="">0 0 0 0 -0 0</pose>
        <geometry>
          <mesh>
            <scale>1 1 1</scale>
            <uri>model://PSM/meshes/tool_pitch_link.STL</uri>
          </mesh>
        </geometry>
      </visual>
    </link>
    <joint name="tool_pitch_joint" type="revolute">
      <child>tool_pitch_link</child>
      <parent>tool_roll_link</parent>
      <axis>
        <xyz>1 -1.1e-05 6e-06</xyz>
        <limit>
          <lower>-1.5708</lower>
          <upper>1.5708</upper>
          <effort>1000</effort>
          <velocity>10</velocity>
        </limit>
        <dynamics>
          <spring_reference>0</spring_reference>
          <spring_stiffness>0</spring_stiffness>
        </dynamics>
        <use_parent_model_frame>1</use_parent_model_frame>
      </axis>
    </joint>
    <link name="tool_yaw_link">
      <pose frame="">2e-06 0.486403 0.00651 1.57078 3e-06 3.14158</pose>
      <inertial>
        <pose frame="">-0 -0 -5e-05 0 -0 0</pose>
        
        
        <mass>0.012491</mass>
        <inertia>
          <ixx>0.001</ixx>
          <ixy>0.00001</ixy>
          <ixz>0.00001</ixz>
          <iyy>0.001</iyy>
          <iyz>0.00001</iyz>
          <izz>0.001</izz>
        </inertia>
      </inertial>
      <collision name="tool_yaw_link_collision">
        <pose frame="">0 0 0 0 -0 0</pose>
        <geometry>
          <mesh>
            <scale>1 1 1</scale>
            <uri>model://PSM/meshes/tool_yaw_link.STL</uri>
          </mesh>
        </geometry>
      </collision>
      <visual name="tool_yaw_link_visual">
        <pose frame="">0 0 0 0 -0 0</pose>
        <geometry>
          <mesh>
            <scale>1 1 1</scale>
            <uri>model://PSM/meshes/tool_yaw_link.STL</uri>
          </mesh>
        </geometry>
      </visual>
    </link>
    <joint name="tool_yaw_joint" type="revolute">
      <child>tool_yaw_link</child>
      <parent>tool_pitch_link</parent>
      <axis>
        <xyz>1.1e-05 1 1.2e-05</xyz>
        <limit>
          <lower>-1.5708</lower>
          <upper>1.5708</upper>
          <effort>1000</effort>
          <velocity>10</velocity>
        </limit>
        <dynamics>
          <spring_reference>0</spring_reference>
          <spring_stiffness>0</spring_stiffness>
        </dynamics>
        <use_parent_model_frame>1</use_parent_model_frame>
      </axis>
    </joint>

    <link name="tool_gripper1_link">
      
      <pose frame="">2e-06 0.486403 0.00651 1.57078 3.14158 3.14158</pose>
      <inertial>
        <pose frame="">0.000196 0.001435 -0.000885 0 -0 0</pose>
        
        <mass>0.010491</mass>
        
        <inertia>
          <ixx>0.001</ixx>
          <ixy>0.00001</ixy>
          <ixz>0.00001</ixz>
          <iyy>0.001</iyy>
          <iyz>0.00001</iyz>
          <izz>0.001</izz>
        </inertia>
      </inertial>
      <collision name="tool_gripper1_link_collision">
        <pose frame="">0 0 0 0 -0 0</pose>
        <geometry>
          <mesh>
            <scale>1 1 1</scale>
            <uri>model://PSM/meshes/tool_gripper1_link.STL</uri>
          </mesh>
        </geometry>
      </collision>
      <visual name="tool_gripper1_link_visual">
        <pose frame="">0 0 0 0 -0 0</pose>
        <geometry>
          <mesh>
            <scale>1 1 1</scale>
            <uri>model://PSM/meshes/tool_gripper1_link.STL</uri>
          </mesh>
        </geometry>
      </visual>
    </link>
    <joint name="tool_gripper1_joint" type="revolute">
      <child>tool_gripper1_link</child>
      <parent>tool_yaw_link</parent>
      <axis>
        <xyz>1.1e-05 -1 1.2e-05</xyz>
        <limit>
          <lower>0</lower>
          <upper>1</upper>
          <effort>0</effort>
          <velocity>0</velocity>
        </limit>
        <dynamics>
          <spring_reference>0</spring_reference>
          <spring_stiffness>0</spring_stiffness>
        </dynamics>
        <use_parent_model_frame>1</use_parent_model_frame>
      </axis>
    </joint>
    <link name="tool_gripper2_link">
      
      <pose frame="">2e-06 0.486403 0.00651 1.57078 3.14158 3.14158</pose>
      <inertial>
        <pose frame="">-0.000196 0.001435 0.000885 0 -0 0</pose>
        
        <mass>0.010491</mass>
        <inertia>
          <ixx>0.001</ixx>
          <ixy>0.00001</ixy>
          <ixz>0.00001</ixz>
          <iyy>0.001</iyy>
          <iyz>0.00001</iyz>
          <izz>0.001</izz>
        </inertia>
      </inertial>
      <collision name="tool_gripper2_link_collision">
        <pose frame="">0 0 0 0 -0 0</pose>
        <geometry>
          <mesh>
            <scale>1 1 1</scale>
            <uri>model://PSM/meshes/tool_gripper2_link.STL</uri>
          </mesh>
        </geometry>
      </collision>
      <visual name="tool_gripper2_link_visual">
        <pose frame="">0 0 0 0 -0 0</pose>
        <geometry>
          <mesh>
            <scale>1 1 1</scale>
            <uri>model://PSM/meshes/tool_gripper2_link.STL</uri>
          </mesh>
        </geometry>
      </visual>
    </link>
    <joint name="tool_gripper2_joint" type="revolute">
      <child>tool_gripper2_link</child>
      <parent>tool_yaw_link</parent>
      <axis>
        <xyz>1.1e-05 1 1.2e-05</xyz>
        <limit>
          <lower>0</lower>
          <upper>1</upper>
          <effort>0</effort>
          <velocity>0</velocity>
        </limit>
        <dynamics>
          <spring_reference>0</spring_reference>
          <spring_stiffness>0</spring_stiffness>
        </dynamics>
        <use_parent_model_frame>1</use_parent_model_frame>
      </axis>
    </joint>
    <link name="pitch_top_Link">
      <pose frame="">-0 -0.068718 0.18 -1.5708 -2.6e-05 1.5708</pose>
      <inertial>
        <pose frame="">-3.66826957797e-06 0.0853897734053 0.0012940064704 0 -0 0</pose>
        <mass>0.009350153752889572</mass>
        <inertia>
          <ixx>0.00265214302176</ixx>
          <ixy>3.07453690438e-09</ixy>
          <ixz>4.29833136945e-10</ixz>
          <iyy>71.6994455176</iyy>
          <iyz>15.4313403366</iyz>
          <izz>100.840824549</izz>
        </inertia>
      </inertial>
      <collision name="pitch_top_Link_collision">
        <pose frame="">0 0 0 0 -0 0</pose>
        <geometry>
          <mesh>
            <scale>1 1 1</scale>
            <uri>model://PSM/meshes/pitch_top_Link.STL</uri>
          </mesh>
        </geometry>
      </collision>
      <visual name="pitch_top_Link_visual">
        <pose frame="">0 0 0 0 -0 0</pose>
        <geometry>
          <mesh>
            <scale>1 1 1</scale>
            <uri>model://PSM/meshes/pitch_top_Link.STL</uri>
          </mesh>
        </geometry>
      </visual>
    </link>
    <joint name="pitch_top_joint" type="revolute">
      <child>pitch_top_Link</child>
      <parent>pitch_back_Link</parent>
      <axis>
        <xyz>-1 -0 -3e-06</xyz>
        <limit>
          <lower>-0.94249</lower>
          <upper>0.93556</upper>
          <effort>1000</effort>
          <velocity>10</velocity>
        </limit>
        <dynamics>
          <spring_reference>0</spring_reference>
          <spring_stiffness>0</spring_stiffness>
        </dynamics>
        <use_parent_model_frame>1</use_parent_model_frame>
      </axis>
    </joint>
    <link name="pitch_front_Link">
      <pose frame="">-0 0.0664 -0 1.57081 -1.28007 -1.5708</pose>
      <inertial>
        <pose frame="">-0.000915815038611 -0.00493041616031 0.00389837089547 0 -0 0</pose>
        <mass>1.0000849392400093</mass>
        <inertia>
          <ixx>0.00210315938069</ixx>
          <ixy>0.00114144142353</ixy>
          <ixz>0.000381525874839</ixz>
          <iyy>8.79439325465e-05</iyy>
          <iyz>0.000908034290497</iyz>
          <izz>0.011754461145</izz>
        </inertia>
      </inertial>
      <collision name="pitch_front_Link_collision">
        <pose frame="">0 0 0 0 -0 0</pose>
        <geometry>
          <mesh>
            <scale>1 1 1</scale>
            <uri>model://PSM/meshes/pitch_front_Link.STL</uri>
          </mesh>
        </geometry>
      </collision>
      <visual name="pitch_front_Link_visual">
        <pose frame="">0 0 0 0 -0 0</pose>
        <geometry>
          <mesh>
            <scale>1 1 1</scale>
            <uri>model://PSM/meshes/pitch_front_Link.STL</uri>
          </mesh>
        </geometry>
      </visual>
    </link>
    <joint name="pitch_front_joint" type="revolute">
      <child>pitch_front_Link</child>
      <parent>yaw_Link</parent>
      <axis>
        <xyz>-1 -0 -3e-06</xyz>
        <limit>
          <lower>-0.93556</lower>
          <upper>0.94249</upper>
          <effort>1000</effort>
          <velocity>10</velocity>
        </limit>
        <dynamics>
          <spring_reference>0</spring_reference>
          <spring_stiffness>0</spring_stiffness>
        </dynamics>
        <use_parent_model_frame>1</use_parent_model_frame>
      </axis>
    </joint>

    <joint name="pitch_front_bottom_joint" type="revolute">
      <pose>0.096 0 0 0 0 0 </pose>
      <child>pitch_bottom_Link</child>
      <parent>pitch_front_Link</parent>
      <axis>
        <xyz>-1 0 0</xyz>
        <limit>
          <lower>-0.93556</lower>
          <upper>0.94249</upper>
          <effort>1000</effort>
          <velocity>1</velocity>
        </limit>
        <dynamics>
          <spring_reference>0</spring_reference>
          <spring_stiffness>0</spring_stiffness>
        </dynamics>
        <use_parent_model_frame>1</use_parent_model_frame>
      </axis>
    </joint>

    <joint name="pitch_top_end_joint" type="revolute">
      <pose>0.00388 -0.036293189  0 0 0 0 </pose>
      <child>pitch_end_Link</child>
      <parent>pitch_top_Link</parent>
      <axis>
        <xyz>-1 0 0</xyz>
        <limit>
          <lower>-0.93556</lower>
          <upper>0.94249</upper>
          <effort>1000</effort>
          <velocity>1</velocity>
        </limit>
        <dynamics>
          <spring_reference>0</spring_reference>
          <spring_stiffness>0</spring_stiffness>
        </dynamics>
        <use_parent_model_frame>1</use_parent_model_frame>
      </axis>
    </joint>
  </model>
</sdf>