<sdf version="1.6">
  <model name="PSM">
    <link name="base_link">
      <pose frame="">0 0 0 0 -0 0</pose>
      <inertial>
        <pose frame="">-0 -0.17016 -0.085607 0 -0 0</pose>
        <mass>2.0161</mass>
        <inertia>
          <ixx>0.03342853</ixx>
          <ixy>0.00942520</ixy>
          <ixz>-0.00334012</ixz>
          <iyy>0</iyy>
          <iyz>0</iyz>
          <izz>0.02897334</izz>
        </inertia>
      </inertial>
      <collision name="base_link_collision">
        <pose frame="">0 0 0 0 -0 0</pose>
        <geometry>
          <mesh>
            <scale>1 1 1</scale>
            <uri>model://PSM/meshes/base_link.STL</uri>
          </mesh>
        </geometry>
      </collision>
      <visual name="base_link_visual">
        <pose frame="">0 0 0 0 -0 0</pose>
        <geometry>
          <mesh>
            <scale>1 1 1</scale>
            <uri>model://PSM/meshes/base_link.STL</uri>
          </mesh>
        </geometry>
      </visual>
    </link>
    <link name="yaw_Link">
      <pose frame="">0 0 0 -1.57079 -1.57079 3.14159</pose>
      <inertial>
        <pose frame="">-0.014562576725 -0.00524249528894 1.60605824426e-19 0 -0 0</pose>
        <mass>1.4999985386443357</mass>
        <inertia>
          <ixx>146.492207231226</ixx>
          <ixy>-141.680586287202</ixy>
          <ixz>1.85437080316714e-17</ixz>
          <iyy>248.089932602168</iyy>
          <iyz>-4.62874228798788e-17</iyz>
          <izz>0.00351781647881753</izz>
        </inertia>
      </inertial>
      <collision name="yaw_Link_collision">
        <pose frame="">0 0 0 0 -0 0</pose>
        <geometry>
          <mesh>
            <scale>1 1 1</scale>
            <uri>model://PSM/meshes/yaw_Link.STL</uri>
          </mesh>
        </geometry>
      </collision>
      <visual name="yaw_Link_visual">
        <pose frame="">0 0 0 0 -0 0</pose>
        <geometry>
          <mesh>
            <scale>1 1 1</scale>
            <uri>model://PSM/meshes/yaw_Link.STL</uri>
          </mesh>
        </geometry>
      </visual>
    </link>
    <joint name="yaw_joint" type="revolute">
      <child>yaw_Link</child>
      <parent>base_link</parent>
      <axis>
        <xyz>-4e-06 1 -0</xyz>
        <limit>
          <lower>-1.605</lower>
          <upper>1.5994</upper>
          <effort>1000</effort>
          <velocity>10</velocity>
        </limit>
        <dynamics>
          <spring_reference>0</spring_reference>
          <spring_stiffness>0</spring_stiffness>
        </dynamics>
        <use_parent_model_frame>1</use_parent_model_frame>
      </axis>
    </joint>
    <link name="pitch_back_Link">
      <pose frame="">0 -0.0296 0 1.57081 -1.28007 -1.5708</pose>
      <inertial>
        <pose frame="">-0.100980279445 -0.00959929425212 -0.00993564946671 0 -0 0</pose>
        
        <mass>1.5000712806654202</mass>
        <inertia>
          <ixx>0.00230492095552235</ixx>
          <ixy>-0.000744361546911101</ixy>
          <ixz>0.00321976095457358</ixz>
          <iyy>0.00348852529798563</iyy>
          <iyz>0.00286715144513410</iyz>
          <izz>0.00269298941638152</izz>
        </inertia>
      </inertial>
      <collision name="pitch_back_Link_collision">
        <pose frame="">0 0 0 0 -0 0</pose>
        <geometry>
          <mesh>
            <scale>1 1 1</scale>
            <uri>model://PSM/meshes/pitch_back_Link.STL</uri>
          </mesh>
        </geometry>
      </collision>
      <visual name="pitch_back_Link_visual">
        <pose frame="">0 0 0 0 -0 0</pose>
        <geometry>
          <mesh>
            <scale>1 1 1</scale>
            <uri>model://PSM/meshes/pitch_back_Link.STL</uri>
          </mesh>
        </geometry>
      </visual>
    </link>
    <joint name="pitch_back_joint" type="revolute">
      <child>pitch_back_Link</child>
      <parent>yaw_Link</parent>
      <axis>
        <xyz>-1 -0 -3e-06</xyz>
        <limit>
          <lower>-0.93556</lower>
          <upper>0.94249</upper>
          <effort>1000</effort>
          <velocity>10</velocity>
        </limit>
        <dynamics>
          <spring_reference>0</spring_reference>
          <spring_stiffness>0</spring_stiffness>
        </dynamics>
        <use_parent_model_frame>1</use_parent_model_frame>
      </axis>
    </joint>
     <link name="counterweight_Link">
      <pose frame="">-0 -0.1296 -0 5e-06 -2.6e-05 1.57079</pose>
      <inertial>
        <pose frame="">-0.010832766304 0.0605111914241 0.00815691571644 0 -0 0</pose>
        <mass>0.39241050954435797</mass>
        <inertia>
          <ixx>0.00353419300776816</ixx>
          <ixy>0.00290201729139431</ixy>
          <ixz>7.25139570379327e-5</ixz>
          <iyy>0.00242248888023060</iyy>
          <iyz>-0.000186539388548878</iyz>
          <izz>1006.87356158912</izz>
        </inertia>
      </inertial>
      <collision name="counterweight_Link_collision">
        <pose frame="">0 0 0 0 -0 0</pose>
        <geometry>
          <mesh>
            <scale>1 1 1</scale>
            <uri>model://PSM/meshes/counterweight_Link.STL</uri>
          </mesh>
        </geometry>
      </collision>
      <visual name="counterweight_Link_visual">
        <pose frame="">0 0 0 0 -0 0</pose>
        <geometry>
          <mesh>
            <scale>1 1 1</scale>
            <uri>model://PSM/meshes/counterweight_Link.STL</uri>
          </mesh>
        </geometry>
      </visual>
    </link>
    <joint name="counterweight_joint" type="prismatic">
      <child>counterweight_Link</child>
      <parent>pitch_back_Link</parent>
      <axis>
        <xyz>5e-06 -2.6e-05 1</xyz>
        <limit>
          <lower>0</lower>
          <upper>0.15</upper>
          <effort>1000</effort>
          <velocity>10</velocity>
        </limit>
        <dynamics>
          <spring_reference>0</spring_reference>
          <spring_stiffness>0</spring_stiffness>
        </dynamics>
        <use_parent_model_frame>1</use_parent_model_frame>
      </axis>
    </joint>
    <link name="pitch_bottom_Link">
      <pose frame="">-0 -0.072598 0.143705 -1.5708 -2.6e-05 1.5708</pose>
      <inertial>
        <pose frame="">9.64855251594e-07 -0.0108229904233 -0.0087156950871 0 -0 0</pose>
        <mass>0.020144727018997104</mass>
        <inertia>
          <ixx>0.00351990398456405</ixx>
          <ixy>-3.33105642663336e-10</ixy>
          <ixz>-3.65088557873375e-10</ixz>
          <iyy>114.412561534684</iyy>
          <iyz>49.4511710589220</iyz>
          <izz>215.138277220443</izz>
        </inertia>
      </inertial>
      <collision name="pitch_bottom_Link_collision">
        <pose frame="">0 0 0 0 -0 0</pose>
        <geometry>
          <mesh>
            <scale>1 1 1</scale>
            <uri>model://PSM/meshes/pitch_bottom_Link.STL</uri>
          </mesh>
        </geometry>
      </collision>
      <visual name="pitch_bottom_Link_visual">
        <pose frame="">0 0 0 0 -0 0</pose>
        <geometry>
          <mesh>
            <scale>1 1 1</scale>
            <uri>model://PSM/meshes/pitch_bottom_Link.STL</uri>
          </mesh>
        </geometry>
      </visual>
    </link>
    <joint name="pitch_bottom_joint" type="revolute">
      <child>pitch_bottom_Link</child>
      <parent>pitch_back_Link</parent>
      <axis>
        <xyz>-1 -0 -3e-06</xyz>
        <limit>
          <lower>-0.94249</lower>
          <upper>0.93556</upper>
          <effort>1000</effort>
          <velocity>10</velocity>
        </limit>
        <dynamics>
          <spring_reference>0</spring_reference>
          <spring_stiffness>0</spring_stiffness>
        </dynamics>
        <use_parent_model_frame>1</use_parent_model_frame>
      </axis>
    </joint>
    <link name="pitch_end_Link">
      <pose frame="">-0 0.443402 0.143719 -1.5708 -2.6e-05 1.5708</pose>
      <inertial>
        <pose frame="">0.162143513695 0.00087206451589 -0.0152753670355 0 -0 0</pose>
        
        <mass>0.010020416625735289</mass>
        <inertia>
          <ixx>0.0123761336166972</ixx>
          <ixy>-0.0123029883349794</ixy>
          <ixz>-0.00990278563278557</ixz>
          <iyy>0.0242954923102975</iyy>
          <iyz>0.0176325434190393</iyz>
          <izz>0.0209474455709598</izz>
        </inertia>
      </inertial>
      <collision name="pitch_end_Link_collision">
        <pose frame="">0 0 0 0 -0 0</pose>
        <geometry>
          <mesh>
            <scale>1 1 1</scale>
            <uri>model://PSM/meshes/pitch_end_Link.STL</uri>
          </mesh>
        </geometry>
      </collision>
      <visual name="pitch_end_Link_visual">
        <pose frame="">0 0 0 0 -0 0</pose>
        <geometry>
          <mesh>
            <scale>1 1 1</scale>
            <uri>model://PSM/meshes/pitch_end_Link.STL</uri>
          </mesh>
        </geometry>
      </visual>
    </link>
    <joint name="pitch_end_joint" type="revolute">
      <child>pitch_end_Link</child>
      <parent>pitch_bottom_Link</parent>
      <axis>
        <xyz>-1 -0 -3e-06</xyz>
        <limit>
          <lower>-0.93556</lower>
          <upper>0.94249</upper>
          <effort>1000</effort>
          <velocity>10</velocity>
        </limit>
        <dynamics>
          <spring_reference>0</spring_reference>
          <spring_stiffness>0</spring_stiffness>
        </dynamics>
        <use_parent_model_frame>1</use_parent_model_frame>
      </axis>
    </joint>
    <link name="main_insertion_Link">
      <pose frame="">-1e-06 0.486395 0.43181 -3.14159 1.9e-05 -1.5708</pose>
      <inertial>
        <pose frame="">0.127645725169 -0.0217124867738 0.0166546898625 0 -0 0</pose>
        <mass>0.3074732925945299</mass>
        <inertia>
          <ixx>0.00317126276369146</ixx>
          <ixy>0.00214852378424295</ixy>
          <ixz>0.00532495130392996</ixz>
          <iyy>0.00490642655122446</iyy>
          <iyz>-0.00412805787075258</iyz>
          <izz>0.0188353814208078</izz>
        </inertia>
      </inertial>
      <collision name="main_insertion_Link_collision">
        <pose frame="">0 0 0 0 -0 0</pose>
        <geometry>
          <mesh>
            <scale>1 1 1</scale>
            <uri>model://PSM/meshes/main_insertion_Link.STL</uri>
          </mesh>
        </geometry>
      </collision>
      <visual name="main_insertion_Link_visual">
        <pose frame="">0 0 0 0 -0 0</pose>
        <geometry>
          <mesh>
            <scale>1 1 1</scale>
            <uri>model://PSM/meshes/main_insertion_Link.STL</uri>
          </mesh>
        </geometry>
      </visual>
    </link>
    <joint name="main_insertion_joint" type="prismatic">
      <child>main_insertion_Link</child>
      <parent>pitch_end_Link</parent>
      <axis>
        <xyz>-6e-06 -1.9e-05 -1</xyz>
        <limit>
          <lower>0</lower>
          <upper>0.24</upper>
          <effort>1000</effort>
          <velocity>1</velocity>
        </limit>
        <dynamics>
          <spring_reference>0</spring_reference>
          <spring_stiffness>0</spring_stiffness>
        </dynamics>
        <use_parent_model_frame>1</use_parent_model_frame>
      </axis>
    </joint>
    <link name="tool_roll_link">
      <pose frame="">2e-06 0.486403 0.01561 3.14159 -1.9e-05 1.57079</pose>
      <inertial>
        <pose frame="">-0 -0 -0.005823 0 -0 0</pose>
        <mass>0.012491</mass>
        <inertia>
          <ixx>0.001</ixx>
          <ixy>0.00001</ixy>
          <ixz>0.00001</ixz>
          <iyy>0.001</iyy>
          <iyz>0.00001</iyz>
          <izz>0.001</izz>
        </inertia>
      </inertial>
      <collision name="tool_roll_link_collision">
        <pose frame="">0 0 0 0 -0 0</pose>
        <geometry>
          <mesh>
            <scale>1 1 1</scale>
            <uri>model://PSM/meshes/tool_roll_link.STL</uri>
          </mesh>
        </geometry>
      </collision>
      <visual name="tool_roll_link_visual">
        <pose frame="">0 0 0 0 -0 0</pose>
        <geometry>
          <mesh>
            <scale>1 1 1</scale>
            <uri>model://PSM/meshes/tool_roll_link.STL</uri>
          </mesh>
        </geometry>
      </visual>
    </link>
    <joint name="tool_roll_joint" type="revolute">
      <child>tool_roll_link</child>
      <parent>main_insertion_Link</parent>
      <axis>
        <xyz>-6e-06 -1.9e-05 -1</xyz>
        <limit>
          <lower>-3.14159</lower>
          <upper>3.14159</upper>
          <effort>1000</effort>
          <velocity>10</velocity>
        </limit>
        <dynamics>
          <spring_reference>0</spring_reference>
          <spring_stiffness>0</spring_stiffness>
        </dynamics>
        <use_parent_model_frame>1</use_parent_model_frame>
      </axis>
    </joint>
    <link name="tool_pitch_link">
      <pose frame="">2e-06 0.486403 0.01561 -1.96086 1.57078 1.18072</pose>
      <inertial>
        <pose frame="">0.003576 -0 4e-06 0 -0 0</pose>
        
        <mass>0.012491</mass>
        <inertia>
          
    
          <ixx>0.001</ixx>
          <ixy>0.00001</ixy>
          <ixz>0.00001</ixz>
          <iyy>0.001</iyy>
          <iyz>0.00001</iyz>
          <izz>0.001</izz>
        </inertia>
      </inertial>
      <collision name="tool_pitch_link_collision">
        <pose frame="">0 0 0 0 -0 0</pose>
        <geometry>
          <mesh>
            <scale>1 1 1</scale>
            <uri>model://PSM/meshes/tool_pitch_link.STL</uri>
          </mesh>
        </geometry>
      </collision>
      <visual name="tool_pitch_link_visual">
        <pose frame="">0 0 0 0 -0 0</pose>
        <geometry>
          <mesh>
            <scale>1 1 1</scale>
            <uri>model://PSM/meshes/tool_pitch_link.STL</uri>
          </mesh>
        </geometry>
      </visual>
    </link>
    <joint name="tool_pitch_joint" type="revolute">
      <child>tool_pitch_link</child>
      <parent>tool_roll_link</parent>
      <axis>
        <xyz>1 -1.1e-05 6e-06</xyz>
        <limit>
          <lower>-1.5708</lower>
          <upper>1.5708</upper>
          <effort>1000</effort>
          <velocity>10</velocity>
        </limit>
        <dynamics>
          <spring_reference>0</spring_reference>
          <spring_stiffness>0</spring_stiffness>
        </dynamics>
        <use_parent_model_frame>1</use_parent_model_frame>
      </axis>
    </joint>
    <link name="tool_yaw_link">
      <pose frame="">2e-06 0.486403 0.00651 1.57078 3e-06 3.14158</pose>
      <inertial>
        <pose frame="">-0 -0 -5e-05 0 -0 0</pose>
        
        
        <mass>0.012491</mass>
        <inertia>
          <ixx>0.001</ixx>
          <ixy>0.00001</ixy>
          <ixz>0.00001</ixz>
          <iyy>0.001</iyy>
          <iyz>0.00001</iyz>
          <izz>0.001</izz>
        </inertia>
      </inertial>
      <collision name="tool_yaw_link_collision">
        <pose frame="">0 0 0 0 -0 0</pose>
        <geometry>
          <mesh>
            <scale>1 1 1</scale>
            <uri>model://PSM/meshes/tool_yaw_link.STL</uri>
          </mesh>
        </geometry>
      </collision>
      <visual name="tool_yaw_link_visual">
        <pose frame="">0 0 0 0 -0 0</pose>
        <geometry>
          <mesh>
            <scale>1 1 1</scale>
            <uri>model://PSM/meshes/tool_yaw_link.STL</uri>
          </mesh>
        </geometry>
      </visual>
    </link>
    <joint name="tool_yaw_joint" type="revolute">
      <child>tool_yaw_link</child>
      <parent>tool_pitch_link</parent>
      <axis>
        <xyz>1.1e-05 1 1.2e-05</xyz>
        <limit>
          <lower>-1.5708</lower>
          <upper>1.5708</upper>
          <effort>1000</effort>
          <velocity>10</velocity>
        </limit>
        <dynamics>
          <spring_reference>0</spring_reference>
          <spring_stiffness>0</spring_stiffness>
        </dynamics>
        <use_parent_model_frame>1</use_parent_model_frame>
      </axis>
    </joint>

    <link name="tool_gripper1_link">
      
      <pose frame="">2e-06 0.486403 0.00651 1.57078 3.14158 3.14158</pose>
      <inertial>
        <pose frame="">0.000196 0.001435 -0.000885 0 -0 0</pose>
        
        <mass>0.010491</mass>
        
        <inertia>
          <ixx>0.001</ixx>
          <ixy>0.00001</ixy>
          <ixz>0.00001</ixz>
          <iyy>0.001</iyy>
          <iyz>0.00001</iyz>
          <izz>0.001</izz>
        </inertia>
      </inertial>
      <collision name="tool_gripper1_link_collision">
        <pose frame="">0 0 0 0 -0 0</pose>
        <geometry>
          <mesh>
            <scale>1 1 1</scale>
            <uri>model://PSM/meshes/tool_gripper1_link.STL</uri>
          </mesh>
        </geometry>
      </collision>
      <visual name="tool_gripper1_link_visual">
        <pose frame="">0 0 0 0 -0 0</pose>
        <geometry>
          <mesh>
            <scale>1 1 1</scale>
            <uri>model://PSM/meshes/tool_gripper1_link.STL</uri>
          </mesh>
        </geometry>
      </visual>
    </link>
    <joint name="tool_gripper1_joint" type="revolute">
      <child>tool_gripper1_link</child>
      <parent>tool_yaw_link</parent>
      <axis>
        <xyz>1.1e-05 -1 1.2e-05</xyz>
        <limit>
          <lower>0</lower>
          <upper>1</upper>
          <effort>0</effort>
          <velocity>0</velocity>
        </limit>
        <dynamics>
          <spring_reference>0</spring_reference>
          <spring_stiffness>0</spring_stiffness>
        </dynamics>
        <use_parent_model_frame>1</use_parent_model_frame>
      </axis>
    </joint>
    <link name="tool_gripper2_link">
      
      <pose frame="">2e-06 0.486403 0.00651 1.57078 3.14158 3.14158</pose>
      <inertial>
        <pose frame="">-0.000196 0.001435 0.000885 0 -0 0</pose>
        
        <mass>0.010491</mass>
        <inertia>
          <ixx>0.001</ixx>
          <ixy>0.00001</ixy>
          <ixz>0.00001</ixz>
          <iyy>0.001</iyy>
          <iyz>0.00001</iyz>
          <izz>0.001</izz>
        </inertia>
      </inertial>
      <collision name="tool_gripper2_link_collision">
        <pose frame="">0 0 0 0 -0 0</pose>
        <geometry>
          <mesh>
            <scale>1 1 1</scale>
            <uri>model://PSM/meshes/tool_gripper2_link.STL</uri>
          </mesh>
        </geometry>
      </collision>
      <visual name="tool_gripper2_link_visual">
        <pose frame="">0 0 0 0 -0 0</pose>
        <geometry>
          <mesh>
            <scale>1 1 1</scale>
            <uri>model://PSM/meshes/tool_gripper2_link.STL</uri>
          </mesh>
        </geometry>
      </visual>
    </link>
    <joint name="tool_gripper2_joint" type="revolute">
      <child>tool_gripper2_link</child>
      <parent>tool_yaw_link</parent>
      <axis>
        <xyz>1.1e-05 1 1.2e-05</xyz>
        <limit>
          <lower>0</lower>
          <upper>1</upper>
          <effort>0</effort>
          <velocity>0</velocity>
        </limit>
        <dynamics>
          <spring_reference>0</spring_reference>
          <spring_stiffness>0</spring_stiffness>
        </dynamics>
        <use_parent_model_frame>1</use_parent_model_frame>
      </axis>
    </joint>
    <link name="pitch_top_Link">
      <pose frame="">-0 -0.068718 0.18 -1.5708 -2.6e-05 1.5708</pose>
      <inertial>
        <pose frame="">0.499261455011 -0.0298663476127 -0.00583983648634 0 -0 0</pose>
        <mass>0.010210429034084515</mass>
        <inertia>
          <ixx>0.00351537483052178</ixx>
          <ixy>-0.000241225696511597</ixy>
          <ixz>-0.000129866269417167</ixz>
          <iyy>89.5191657729137</iyy>
          <iyz>52.7133028317604</iyz>
          <izz>241.797019646115</izz>
        </inertia>
      </inertial>
      <collision name="pitch_top_Link_collision">
        <pose frame="">0 0 0 0 -0 0</pose>
        <geometry>
          <mesh>
            <scale>1 1 1</scale>
            <uri>model://PSM/meshes/pitch_top_Link.STL</uri>
          </mesh>
        </geometry>
      </collision>
      <visual name="pitch_top_Link_visual">
        <pose frame="">0 0 0 0 -0 0</pose>
        <geometry>
          <mesh>
            <scale>1 1 1</scale>
            <uri>model://PSM/meshes/pitch_top_Link.STL</uri>
          </mesh>
        </geometry>
      </visual>
    </link>
    <joint name="pitch_top_joint" type="revolute">
      <child>pitch_top_Link</child>
      <parent>pitch_back_Link</parent>
      <axis>
        <xyz>-1 -0 -3e-06</xyz>
        <limit>
          <lower>-0.94249</lower>
          <upper>0.93556</upper>
          <effort>1000</effort>
          <velocity>10</velocity>
        </limit>
        <dynamics>
          <spring_reference>0</spring_reference>
          <spring_stiffness>0</spring_stiffness>
        </dynamics>
        <use_parent_model_frame>1</use_parent_model_frame>
      </axis>
    </joint>
    <link name="pitch_front_Link">
      <pose frame="">-0 0.0664 -0 1.57081 -1.28007 -1.5708</pose>
      <inertial>
        <pose frame="">-0.000743360721006 -0.0199380655736 -0.00913554132919 0 -0 0</pose>
        <mass>0.1499980529100466</mass>
        <inertia>
          <ixx>0.00253131629948150</ixx>
          <ixy>-0.000794251874135346</ixy>
          <ixz>0.000352764620827068</ixz>
          <iyy>0.00341868677827976</iyy>
          <iyz>0.00278047538539245</iyz>
          <izz>0.00270691969369100</izz>
        </inertia>
      </inertial>
      <collision name="pitch_front_Link_collision">
        <pose frame="">0 0 0 0 -0 0</pose>
        <geometry>
          <mesh>
            <scale>1 1 1</scale>
            <uri>model://PSM/meshes/pitch_front_Link.STL</uri>
          </mesh>
        </geometry>
      </collision>
      <visual name="pitch_front_Link_visual">
        <pose frame="">0 0 0 0 -0 0</pose>
        <geometry>
          <mesh>
            <scale>1 1 1</scale>
            <uri>model://PSM/meshes/pitch_front_Link.STL</uri>
          </mesh>
        </geometry>
      </visual>
    </link>
    <joint name="pitch_front_joint" type="revolute">
      <child>pitch_front_Link</child>
      <parent>yaw_Link</parent>
      <axis>
        <xyz>-1 -0 -3e-06</xyz>
        <limit>
          <lower>-0.93556</lower>
          <upper>0.94249</upper>
          <effort>1000</effort>
          <velocity>10</velocity>
        </limit>
        <dynamics>
          <spring_reference>0</spring_reference>
          <spring_stiffness>0</spring_stiffness>
        </dynamics>
        <use_parent_model_frame>1</use_parent_model_frame>
      </axis>
    </joint>

    <joint name="pitch_front_bottom_joint" type="revolute">
      <pose>0.096 0 0 0 0 0 </pose>
      <child>pitch_bottom_Link</child>
      <parent>pitch_front_Link</parent>
      <axis>
        <xyz>-1 0 0</xyz>
        <limit>
          <lower>-0.93556</lower>
          <upper>0.94249</upper>
          <effort>1000</effort>
          <velocity>1</velocity>
        </limit>
        <dynamics>
          <spring_reference>0</spring_reference>
          <spring_stiffness>0</spring_stiffness>
        </dynamics>
        <use_parent_model_frame>1</use_parent_model_frame>
      </axis>
    </joint>

    <joint name="pitch_top_end_joint" type="revolute">
      <pose>0.00388 -0.036293189  0 0 0 0 </pose>
      <child>pitch_end_Link</child>
      <parent>pitch_top_Link</parent>
      <axis>
        <xyz>-1 0 0</xyz>
        <limit>
          <lower>-0.93556</lower>
          <upper>0.94249</upper>
          <effort>1000</effort>
          <velocity>1</velocity>
        </limit>
        <dynamics>
          <spring_reference>0</spring_reference>
          <spring_stiffness>0</spring_stiffness>
        </dynamics>
        <use_parent_model_frame>1</use_parent_model_frame>
      </axis>
    </joint>
  </model>
</sdf>