<sdf version="1.6">
  <model name="PSM">
    <link name="base_link">
      <pose frame="">0 0 0 0 -0 0</pose>
      <inertial>
        <pose frame="">-0 -0.17016 -0.085607 0 -0 0</pose>
        <mass>2.0161</mass>
        <inertia>
          <ixx>0.03342853</ixx>
          <ixy>0.00942520</ixy>
          <ixz>-0.00334012</ixz>
          <iyy>0</iyy>
          <iyz>0</iyz>
          <izz>0.02897334</izz>
        </inertia>
      </inertial>
      <collision name="base_link_collision">
        <pose frame="">0 0 0 0 -0 0</pose>
        <geometry>
          <mesh>
            <scale>1 1 1</scale>
            <uri>model://PSM/meshes/base_link.STL</uri>
          </mesh>
        </geometry>
      </collision>
      <visual name="base_link_visual">
        <pose frame="">0 0 0 0 -0 0</pose>
        <geometry>
          <mesh>
            <scale>1 1 1</scale>
            <uri>model://PSM/meshes/base_link.STL</uri>
          </mesh>
        </geometry>
      </visual>
    </link>
    <link name="yaw_Link">
      <pose frame="">0 0 0 -1.57079 -1.57079 3.14159</pose>
      <inertial>
        <pose frame="">-0.00973688486094 0.00333820393993 -1.31417219653e-19 0 -0 0</pose>
        <mass>0.5000515997300797</mass>
        <inertia>
          <ixx>5.52522421044</ixx>
          <ixy>0.0624136842816</ixy>
          <ixz>5.89633642974e-19</ixz>
          <iyy>14.6894443609</iyy>
          <iyz>4.31109257112e-17</iyz>
          <izz>0.0016045467734</izz>
        </inertia>
      </inertial>
      <collision name="yaw_Link_collision">
        <pose frame="">0 0 0 0 -0 0</pose>
        <geometry>
          <mesh>
            <scale>1 1 1</scale>
            <uri>model://PSM/meshes/yaw_Link.STL</uri>
          </mesh>
        </geometry>
      </collision>
      <visual name="yaw_Link_visual">
        <pose frame="">0 0 0 0 -0 0</pose>
        <geometry>
          <mesh>
            <scale>1 1 1</scale>
            <uri>model://PSM/meshes/yaw_Link.STL</uri>
          </mesh>
        </geometry>
      </visual>
    </link>
    <joint name="yaw_joint" type="revolute">
      <child>yaw_Link</child>
      <parent>base_link</parent>
      <axis>
        <xyz>-4e-06 1 -0</xyz>
        <limit>
          <lower>-1.605</lower>
          <upper>1.5994</upper>
          <effort>1000</effort>
          <velocity>10</velocity>
        </limit>
        <dynamics>
          <spring_reference>0</spring_reference>
          <spring_stiffness>0</spring_stiffness>
        </dynamics>
        <use_parent_model_frame>1</use_parent_model_frame>
      </axis>
    </joint>
    <link name="pitch_back_Link">
      <pose frame="">0 -0.0296 0 1.57081 -1.28007 -1.5708</pose>
      <inertial>
        <pose frame="">-0.00670000131201 0.000716021468355 0.000455046624846 0 -0 0</pose>
        
        <mass>10.001048898093302</mass>
        <inertia>
          <ixx>0.00163465440083</ixx>
          <ixy>0.0134289312615</ixy>
          <ixz>0.00144955914894</ixz>
          <iyy>0.0541526003691</iyy>
          <iyz>0.00334729033448</iyz>
          <izz>0.00101774421569</izz>
        </inertia>
      </inertial>
      <collision name="pitch_back_Link_collision">
        <pose frame="">0 0 0 0 -0 0</pose>
        <geometry>
          <mesh>
            <scale>1 1 1</scale>
            <uri>model://PSM/meshes/pitch_back_Link.STL</uri>
          </mesh>
        </geometry>
      </collision>
      <visual name="pitch_back_Link_visual">
        <pose frame="">0 0 0 0 -0 0</pose>
        <geometry>
          <mesh>
            <scale>1 1 1</scale>
            <uri>model://PSM/meshes/pitch_back_Link.STL</uri>
          </mesh>
        </geometry>
      </visual>
    </link>
    <joint name="pitch_back_joint" type="revolute">
      <child>pitch_back_Link</child>
      <parent>yaw_Link</parent>
      <axis>
        <xyz>-1 -0 -3e-06</xyz>
        <limit>
          <lower>-0.93556</lower>
          <upper>0.94249</upper>
          <effort>1000</effort>
          <velocity>10</velocity>
        </limit>
        <dynamics>
          <spring_reference>0</spring_reference>
          <spring_stiffness>0</spring_stiffness>
        </dynamics>
        <use_parent_model_frame>1</use_parent_model_frame>
      </axis>
    </joint>
    <link name="pitch_bottom_Link">
      <pose frame="">-0 -0.072598 0.143705 -1.5708 -2.6e-05 1.5708</pose>
      <inertial>
        <pose frame="">0.515000999251 -0.0272017584445 0.0184920730123 0 -0 0</pose>
        <mass>0.019958559055707634</mass>
        <inertia>
          <ixx>0.00160600783569</ixx>
          <ixy>2.32288659567e-05</ixy>
          <ixz>1.42471889541e-05</ixz>
          <iyy>49.5615652192</iyy>
          <iyz>4.55065643051</iyz>
          <izz>48.9050418047</izz>
        </inertia>
      </inertial>
      <collision name="pitch_bottom_Link_collision">
        <pose frame="">0 0 0 0 -0 0</pose>
        <geometry>
          <mesh>
            <scale>1 1 1</scale>
            <uri>model://PSM/meshes/pitch_bottom_Link.STL</uri>
          </mesh>
        </geometry>
      </collision>
      <visual name="pitch_bottom_Link_visual">
        <pose frame="">0 0 0 0 -0 0</pose>
        <geometry>
          <mesh>
            <scale>1 1 1</scale>
            <uri>model://PSM/meshes/pitch_bottom_Link.STL</uri>
          </mesh>
        </geometry>
      </visual>
    </link>
    <joint name="pitch_bottom_joint" type="revolute">
      <child>pitch_bottom_Link</child>
      <parent>pitch_back_Link</parent>
      <axis>
        <xyz>-1 -0 -3e-06</xyz>
        <limit>
          <lower>-0.94249</lower>
          <upper>0.93556</upper>
          <effort>1000</effort>
          <velocity>10</velocity>
        </limit>
        <dynamics>
          <spring_reference>0</spring_reference>
          <spring_stiffness>0</spring_stiffness>
        </dynamics>
        <use_parent_model_frame>1</use_parent_model_frame>
      </axis>
    </joint>
    <link name="pitch_end_Link">
      <pose frame="">-0 0.443402 0.143719 -1.5708 -2.6e-05 1.5708</pose>
      <inertial>
        <pose frame="">0.0459106280813 0.0396947136647 0.027044567779 0 -0 0</pose>
        
        <mass>0.009976045027156443</mass>
        <inertia>
          <ixx>0.0233072146277</ixx>
          <ixy>0.00133424733186</ixy>
          <ixz>0.00151872936527</ixz>
          <iyy>0.00154266886841</iyy>
          <iyz>0.000554531719679</iyz>
          <izz>0.00115820493676</izz>
        </inertia>
      </inertial>
      <collision name="pitch_end_Link_collision">
        <pose frame="">0 0 0 0 -0 0</pose>
        <geometry>
          <mesh>
            <scale>1 1 1</scale>
            <uri>model://PSM/meshes/pitch_end_Link.STL</uri>
          </mesh>
        </geometry>
      </collision>
      <visual name="pitch_end_Link_visual">
        <pose frame="">0 0 0 0 -0 0</pose>
        <geometry>
          <mesh>
            <scale>1 1 1</scale>
            <uri>model://PSM/meshes/pitch_end_Link.STL</uri>
          </mesh>
        </geometry>
      </visual>
    </link>
    <joint name="pitch_end_joint" type="revolute">
      <child>pitch_end_Link</child>
      <parent>pitch_bottom_Link</parent>
      <axis>
        <xyz>-1 -0 -3e-06</xyz>
        <limit>
          <lower>-0.93556</lower>
          <upper>0.94249</upper>
          <effort>1000</effort>
          <velocity>10</velocity>
        </limit>
        <dynamics>
          <spring_reference>0</spring_reference>
          <spring_stiffness>0</spring_stiffness>
        </dynamics>
        <use_parent_model_frame>1</use_parent_model_frame>
      </axis>
    </joint>
    <link name="main_insertion_Link">
      <pose frame="">-1e-06 0.486395 0.43181 -3.14159 1.9e-05 -1.5708</pose>
      <inertial>
        <pose frame="">-0.0269460097482 -2.31829784073 0.401750956527 0 -0 0</pose>
        <mass>0.01721394580835471</mass>
        <inertia>
          

          <ixx>0.0244274594052</ixx>
          <ixy>0.000451881124172</ixy>
          <ixz>0.00749453004228</ixz>
          <iyy>0.000257025262632</iyy>
          <iyz>0.00378226188968</iyz>
          <izz>0.0295306383836</izz>
        </inertia>
      </inertial>
      <collision name="main_insertion_Link_collision">
        <pose frame="">0 0 0 0 -0 0</pose>
        <geometry>
          <mesh>
            <scale>1 1 1</scale>
            <uri>model://PSM/meshes/main_insertion_Link.STL</uri>
          </mesh>
        </geometry>
      </collision>
      <visual name="main_insertion_Link_visual">
        <pose frame="">0 0 0 0 -0 0</pose>
        <geometry>
          <mesh>
            <scale>1 1 1</scale>
            <uri>model://PSM/meshes/main_insertion_Link.STL</uri>
          </mesh>
        </geometry>
      </visual>
    </link>
    <joint name="main_insertion_joint" type="prismatic">
      <child>main_insertion_Link</child>
      <parent>pitch_end_Link</parent>
      <axis>
        <xyz>-6e-06 -1.9e-05 -1</xyz>
        <limit>
          <lower>0</lower>
          <upper>0.24</upper>
          <effort>1000</effort>
          <velocity>1</velocity>
        </limit>
        <dynamics>
          <spring_reference>0</spring_reference>
          <spring_stiffness>0</spring_stiffness>
        </dynamics>
        <use_parent_model_frame>1</use_parent_model_frame>
      </axis>
    </joint>
    <link name="tool_roll_link">
      <pose frame="">2e-06 0.486403 0.01561 3.14159 -1.9e-05 1.57079</pose>
      <inertial>
        <pose frame="">-0 -0 -0.005823 0 -0 0</pose>
        
        <mass>0.012491</mass>
        <inertia>
          <ixx>0.001</ixx>
          <ixy>0.00001</ixy>
          <ixz>0.00001</ixz>
          <iyy>0.001</iyy>
          <iyz>0.00001</iyz>
          <izz>0.001</izz>
        </inertia>
      </inertial>
      <collision name="tool_roll_link_collision">
        <pose frame="">0 0 0 0 -0 0</pose>
        <geometry>
          <mesh>
            <scale>1 1 1</scale>
            <uri>model://PSM/meshes/tool_roll_link.STL</uri>
          </mesh>
        </geometry>
      </collision>
      <visual name="tool_roll_link_visual">
        <pose frame="">0 0 0 0 -0 0</pose>
        <geometry>
          <mesh>
            <scale>1 1 1</scale>
            <uri>model://PSM/meshes/tool_roll_link.STL</uri>
          </mesh>
        </geometry>
      </visual>
    </link>
    <joint name="tool_roll_joint" type="revolute">
      <child>tool_roll_link</child>
      <parent>main_insertion_Link</parent>
      <axis>
        <xyz>-6e-06 -1.9e-05 -1</xyz>
        <limit>
          <lower>-3.14159</lower>
          <upper>3.14159</upper>
          <effort>1000</effort>
          <velocity>10</velocity>
        </limit>
        <dynamics>
          <spring_reference>0</spring_reference>
          <spring_stiffness>0</spring_stiffness>
        </dynamics>
        <use_parent_model_frame>1</use_parent_model_frame>
      </axis>
    </joint>
    <link name="tool_pitch_link">
      <pose frame="">2e-06 0.486403 0.01561 -1.96086 1.57078 1.18072</pose>
      <inertial>
        <pose frame="">0.003576 -0 4e-06 0 -0 0</pose>
        
        <mass>0.012491</mass>
        <inertia>
          
    
          <ixx>0.001</ixx>
          <ixy>0.00001</ixy>
          <ixz>0.00001</ixz>
          <iyy>0.001</iyy>
          <iyz>0.00001</iyz>
          <izz>0.001</izz>
        </inertia>
      </inertial>
      <collision name="tool_pitch_link_collision">
        <pose frame="">0 0 0 0 -0 0</pose>
        <geometry>
          <mesh>
            <scale>1 1 1</scale>
            <uri>model://PSM/meshes/tool_pitch_link.STL</uri>
          </mesh>
        </geometry>
      </collision>
      <visual name="tool_pitch_link_visual">
        <pose frame="">0 0 0 0 -0 0</pose>
        <geometry>
          <mesh>
            <scale>1 1 1</scale>
            <uri>model://PSM/meshes/tool_pitch_link.STL</uri>
          </mesh>
        </geometry>
      </visual>
    </link>
    <joint name="tool_pitch_joint" type="revolute">
      <child>tool_pitch_link</child>
      <parent>tool_roll_link</parent>
      <axis>
        <xyz>1 -1.1e-05 6e-06</xyz>
        <limit>
          <lower>-1.5708</lower>
          <upper>1.5708</upper>
          <effort>1000</effort>
          <velocity>10</velocity>
        </limit>
        <dynamics>
          <spring_reference>0</spring_reference>
          <spring_stiffness>0</spring_stiffness>
        </dynamics>
        <use_parent_model_frame>1</use_parent_model_frame>
      </axis>
    </joint>
    <link name="tool_yaw_link">
      <pose frame="">2e-06 0.486403 0.00651 1.57078 3e-06 3.14158</pose>
      <inertial>
        <pose frame="">-0 -0 -5e-05 0 -0 0</pose>
        
        
        <mass>0.012491</mass>
        <inertia>
          <ixx>0.001</ixx>
          <ixy>0.00001</ixy>
          <ixz>0.00001</ixz>
          <iyy>0.001</iyy>
          <iyz>0.00001</iyz>
          <izz>0.001</izz>
        </inertia>
      </inertial>
      <collision name="tool_yaw_link_collision">
        <pose frame="">0 0 0 0 -0 0</pose>
        <geometry>
          <mesh>
            <scale>1 1 1</scale>
            <uri>model://PSM/meshes/tool_yaw_link.STL</uri>
          </mesh>
        </geometry>
      </collision>
      <visual name="tool_yaw_link_visual">
        <pose frame="">0 0 0 0 -0 0</pose>
        <geometry>
          <mesh>
            <scale>1 1 1</scale>
            <uri>model://PSM/meshes/tool_yaw_link.STL</uri>
          </mesh>
        </geometry>
      </visual>
    </link>
    <joint name="tool_yaw_joint" type="revolute">
      <child>tool_yaw_link</child>
      <parent>tool_pitch_link</parent>
      <axis>
        <xyz>1.1e-05 1 1.2e-05</xyz>
        <limit>
          <lower>-1.5708</lower>
          <upper>1.5708</upper>
          <effort>1000</effort>
          <velocity>10</velocity>
        </limit>
        <dynamics>
          <spring_reference>0</spring_reference>
          <spring_stiffness>0</spring_stiffness>
        </dynamics>
        <use_parent_model_frame>1</use_parent_model_frame>
      </axis>
    </joint>

    <link name="tool_gripper1_link">
      
      <pose frame="">2e-06 0.486403 0.00651 1.57078 3.14158 3.14158</pose>
      <inertial>
        <pose frame="">0.000196 0.001435 -0.000885 0 -0 0</pose>
        
        <mass>0.010491</mass>
        
        <inertia>
          <ixx>0.001</ixx>
          <ixy>0.00001</ixy>
          <ixz>0.00001</ixz>
          <iyy>0.001</iyy>
          <iyz>0.00001</iyz>
          <izz>0.001</izz>
        </inertia>
      </inertial>
      <collision name="tool_gripper1_link_collision">
        <pose frame="">0 0 0 0 -0 0</pose>
        <geometry>
          <mesh>
            <scale>1 1 1</scale>
            <uri>model://PSM/meshes/tool_gripper1_link.STL</uri>
          </mesh>
        </geometry>
      </collision>
      <visual name="tool_gripper1_link_visual">
        <pose frame="">0 0 0 0 -0 0</pose>
        <geometry>
          <mesh>
            <scale>1 1 1</scale>
            <uri>model://PSM/meshes/tool_gripper1_link.STL</uri>
          </mesh>
        </geometry>
      </visual>
    </link>
    <joint name="tool_gripper1_joint" type="revolute">
      <child>tool_gripper1_link</child>
      <parent>tool_yaw_link</parent>
      <axis>
        <xyz>1.1e-05 -1 1.2e-05</xyz>
        <limit>
          <lower>0</lower>
          <upper>1</upper>
          <effort>0</effort>
          <velocity>0</velocity>
        </limit>
        <dynamics>
          <spring_reference>0</spring_reference>
          <spring_stiffness>0</spring_stiffness>
        </dynamics>
        <use_parent_model_frame>1</use_parent_model_frame>
      </axis>
    </joint>
    <link name="tool_gripper2_link">
      
      <pose frame="">2e-06 0.486403 0.00651 1.57078 3.14158 3.14158</pose>
      <inertial>
        <pose frame="">-0.000196 0.001435 0.000885 0 -0 0</pose>
        
        <mass>0.010491</mass>
        <inertia>
          <ixx>0.001</ixx>
          <ixy>0.00001</ixy>
          <ixz>0.00001</ixz>
          <iyy>0.001</iyy>
          <iyz>0.00001</iyz>
          <izz>0.001</izz>
        </inertia>
      </inertial>
      <collision name="tool_gripper2_link_collision">
        <pose frame="">0 0 0 0 -0 0</pose>
        <geometry>
          <mesh>
            <scale>1 1 1</scale>
            <uri>model://PSM/meshes/tool_gripper2_link.STL</uri>
          </mesh>
        </geometry>
      </collision>
      <visual name="tool_gripper2_link_visual">
        <pose frame="">0 0 0 0 -0 0</pose>
        <geometry>
          <mesh>
            <scale>1 1 1</scale>
            <uri>model://PSM/meshes/tool_gripper2_link.STL</uri>
          </mesh>
        </geometry>
      </visual>
    </link>
    <joint name="tool_gripper2_joint" type="revolute">
      <child>tool_gripper2_link</child>
      <parent>tool_yaw_link</parent>
      <axis>
        <xyz>1.1e-05 1 1.2e-05</xyz>
        <limit>
          <lower>0</lower>
          <upper>1</upper>
          <effort>0</effort>
          <velocity>0</velocity>
        </limit>
        <dynamics>
          <spring_reference>0</spring_reference>
          <spring_stiffness>0</spring_stiffness>
        </dynamics>
        <use_parent_model_frame>1</use_parent_model_frame>
      </axis>
    </joint>
    <link name="pitch_top_Link">
      <pose frame="">-0 -0.068718 0.18 -1.5708 -2.6e-05 1.5708</pose>
      <inertial>
        <pose frame="">0.515003857285 -0.00186110296369 0.0286180258868 0 -0 0</pose>
        <mass>0.009938931228847477</mass>
        <inertia>
          <ixx>0.00160402711167</ixx>
          <ixy>2.73688965995e-05</ixy>
          <ixz>2.09193446362e-05</ixz>
          <iyy>49.4120347505</iyy>
          <iyz>4.22777289216</iyz>
          <izz>49.6868973994</izz>
        </inertia>
      </inertial>
      <collision name="pitch_top_Link_collision">
        <pose frame="">0 0 0 0 -0 0</pose>
        <geometry>
          <mesh>
            <scale>1 1 1</scale>
            <uri>model://PSM/meshes/pitch_top_Link.STL</uri>
          </mesh>
        </geometry>
      </collision>
      <visual name="pitch_top_Link_visual">
        <pose frame="">0 0 0 0 -0 0</pose>
        <geometry>
          <mesh>
            <scale>1 1 1</scale>
            <uri>model://PSM/meshes/pitch_top_Link.STL</uri>
          </mesh>
        </geometry>
      </visual>
    </link>
    <joint name="pitch_top_joint" type="revolute">
      <child>pitch_top_Link</child>
      <parent>pitch_back_Link</parent>
      <axis>
        <xyz>-1 -0 -3e-06</xyz>
        <limit>
          <lower>-0.94249</lower>
          <upper>0.93556</upper>
          <effort>1000</effort>
          <velocity>10</velocity>
        </limit>
        <dynamics>
          <spring_reference>0</spring_reference>
          <spring_stiffness>0</spring_stiffness>
        </dynamics>
        <use_parent_model_frame>1</use_parent_model_frame>
      </axis>
    </joint>
    <link name="pitch_front_Link">
      <pose frame="">-0 0.0664 -0 1.57081 -1.28007 -1.5708</pose>
      <inertial>
        <pose frame="">-1.64944624566e-06 0.0019194252924 0.00349489274444 0 -0 0</pose>
        <mass>10.001048829771266</mass>
        <inertia>
          <ixx>0.00150026877451</ixx>
          <ixy>0.000399452957577</ixy>
          <ixz>0.000620740104389</ixz>
          <iyy>9.86557295119e-05</iyy>
          <iyz>0.000111177806591</iyz>
          <izz>0.00124037964415</izz>
        </inertia>
      </inertial>
      <collision name="pitch_front_Link_collision">
        <pose frame="">0 0 0 0 -0 0</pose>
        <geometry>
          <mesh>
            <scale>1 1 1</scale>
            <uri>model://PSM/meshes/pitch_front_Link.STL</uri>
          </mesh>
        </geometry>
      </collision>
      <visual name="pitch_front_Link_visual">
        <pose frame="">0 0 0 0 -0 0</pose>
        <geometry>
          <mesh>
            <scale>1 1 1</scale>
            <uri>model://PSM/meshes/pitch_front_Link.STL</uri>
          </mesh>
        </geometry>
      </visual>
    </link>
    <joint name="pitch_front_joint" type="revolute">
      <child>pitch_front_Link</child>
      <parent>yaw_Link</parent>
      <axis>
        <xyz>-1 -0 -3e-06</xyz>
        <limit>
          <lower>-0.93556</lower>
          <upper>0.94249</upper>
          <effort>1000</effort>
          <velocity>10</velocity>
        </limit>
        <dynamics>
          <spring_reference>0</spring_reference>
          <spring_stiffness>0</spring_stiffness>
        </dynamics>
        <use_parent_model_frame>1</use_parent_model_frame>
      </axis>
    </joint>

    <joint name="pitch_front_bottom_joint" type="revolute">
      <pose>0.096 0 0 0 0 0 </pose>
      <child>pitch_bottom_Link</child>
      <parent>pitch_front_Link</parent>
      <axis>
        <xyz>-1 0 0</xyz>
        <limit>
          <lower>-0.93556</lower>
          <upper>0.94249</upper>
          <effort>1000</effort>
          <velocity>1</velocity>
        </limit>
        <dynamics>
          <spring_reference>0</spring_reference>
          <spring_stiffness>0</spring_stiffness>
        </dynamics>
        <use_parent_model_frame>1</use_parent_model_frame>
      </axis>
    </joint>

    <joint name="pitch_top_end_joint" type="revolute">
      <pose>0.00388 -0.036293189  0 0 0 0 </pose>
      <child>pitch_end_Link</child>
      <parent>pitch_top_Link</parent>
      <axis>
        <xyz>-1 0 0</xyz>
        <limit>
          <lower>-0.93556</lower>
          <upper>0.94249</upper>
          <effort>1000</effort>
          <velocity>1</velocity>
        </limit>
        <dynamics>
          <spring_reference>0</spring_reference>
          <spring_stiffness>0</spring_stiffness>
        </dynamics>
        <use_parent_model_frame>1</use_parent_model_frame>
      </axis>
    </joint>
  </model>
</sdf>